<?xml version="1.0" ?>
<!-- =================================================================================== -->
<!-- |    This document was autogenerated by xacro from ur5_six.xacro                  | -->
<!-- |    EDITING THIS FILE BY HAND IS NOT RECOMMENDED                                 | -->
<!-- =================================================================================== -->
<robot name="ur5_six">
  <material name="silver">
    <color rgba="0.700 0.700 0.700 1.000"/>
  </material>
  <transmission name="j1_tran">
    <type>transmission_interface/SimpleTransmission</type>
    <joint name="j1">
      <hardwareInterface>hardware_interface/EffortJointInterface</hardwareInterface>
    </joint>
    <actuator name="j1_actr">
      <hardwareInterface>hardware_interface/EffortJointInterface</hardwareInterface>
      <mechanicalReduction>1</mechanicalReduction>
    </actuator>
  </transmission>
  <transmission name="j2_tran">
    <type>transmission_interface/SimpleTransmission</type>
    <joint name="j2">
      <hardwareInterface>hardware_interface/EffortJointInterface</hardwareInterface>
    </joint>
    <actuator name="j2_actr">
      <hardwareInterface>hardware_interface/EffortJointInterface</hardwareInterface>
      <mechanicalReduction>1</mechanicalReduction>
    </actuator>
  </transmission>
  <transmission name="j3_tran">
    <type>transmission_interface/SimpleTransmission</type>
    <joint name="j3">
      <hardwareInterface>hardware_interface/EffortJointInterface</hardwareInterface>
    </joint>
    <actuator name="j3_actr">
      <hardwareInterface>hardware_interface/EffortJointInterface</hardwareInterface>
      <mechanicalReduction>1</mechanicalReduction>
    </actuator>
  </transmission>
  <transmission name="j4_tran">
    <type>transmission_interface/SimpleTransmission</type>
    <joint name="j4">
      <hardwareInterface>hardware_interface/EffortJointInterface</hardwareInterface>
    </joint>
    <actuator name="j4_actr">
      <hardwareInterface>hardware_interface/EffortJointInterface</hardwareInterface>
      <mechanicalReduction>1</mechanicalReduction>
    </actuator>
  </transmission>
  <transmission name="j5_tran">
    <type>transmission_interface/SimpleTransmission</type>
    <joint name="j5">
      <hardwareInterface>hardware_interface/EffortJointInterface</hardwareInterface>
    </joint>
    <actuator name="j5_actr">
      <hardwareInterface>hardware_interface/EffortJointInterface</hardwareInterface>
      <mechanicalReduction>1</mechanicalReduction>
    </actuator>
  </transmission>
  <transmission name="j6_tran">
    <type>transmission_interface/SimpleTransmission</type>
    <joint name="j6">
      <hardwareInterface>hardware_interface/EffortJointInterface</hardwareInterface>
    </joint>
    <actuator name="j6_actr">
      <hardwareInterface>hardware_interface/EffortJointInterface</hardwareInterface>
      <mechanicalReduction>1</mechanicalReduction>
    </actuator>
  </transmission>
  <gazebo>
    <plugin filename="libgazebo_ros_control.so" name="control"/>
  </gazebo>
  <gazebo reference="base_link">
    <material>Gazebo/Silver</material>
    <mu1>0.2</mu1>
    <mu2>0.2</mu2>
    <self_collide>true</self_collide>
    <gravity>true</gravity>
  </gazebo>
  <gazebo reference="link1_1">
    <material>Gazebo/Silver</material>
    <mu1>0.2</mu1>
    <mu2>0.2</mu2>
    <self_collide>true</self_collide>
  </gazebo>
  <gazebo reference="link2_1">
    <material>Gazebo/Silver</material>
    <mu1>0.2</mu1>
    <mu2>0.2</mu2>
    <self_collide>true</self_collide>
  </gazebo>
  <gazebo reference="link3_1">
    <material>Gazebo/Silver</material>
    <mu1>0.2</mu1>
    <mu2>0.2</mu2>
    <self_collide>true</self_collide>
  </gazebo>
  <gazebo reference="link4_1">
    <material>Gazebo/Silver</material>
    <mu1>0.2</mu1>
    <mu2>0.2</mu2>
    <self_collide>true</self_collide>
  </gazebo>
  <gazebo reference="link5_1">
    <material>Gazebo/Silver</material>
    <mu1>0.2</mu1>
    <mu2>0.2</mu2>
    <self_collide>true</self_collide>
  </gazebo>
  <gazebo reference="link6_1">
    <material>Gazebo/Silver</material>
    <mu1>0.2</mu1>
    <mu2>0.2</mu2>
    <self_collide>true</self_collide>
  </gazebo>
  <link name="base_link">
    <!-- <inertial>
      <origin rpy="0 0 0" xyz="0.0 0.0 0.002"/>
      <mass value="0.11304"/>
      <inertia ixx="1e-4" ixy="0.0" ixz="0.0" iyy="1e-4" iyz="0.0" izz="2e-4"/>
    </inertial> -->
    <visual>
      <origin rpy="0 0 0" xyz="0 0 0"/>
      <geometry>
        <mesh filename="/root/MyArmDescription/myarm_rl/data/ur5_six_description/meshes/base_link.stl" scale="0.001 0.001 0.001"/>
      </geometry>
      <material name="silver"/>
    </visual>
    <collision>
      <origin rpy="0 0 0" xyz="0 0 0"/>
      <geometry>
        <mesh filename="/root/MyArmDescription/myarm_rl/data/ur5_six_description/meshes/base_link.stl" scale="0.001 0.001 0.001"/>
      </geometry>
    </collision>
  </link>
  <link name="link1_1">
    <!-- <inertial>
      <origin rpy="0 0 0" xyz="-2.355900152860585e-05 0.0013235336047745388 0.06464552897488296"/>
      <mass value="1.7789070918759327"/>
      <inertia ixx="1e-4" ixy="0.0" ixz="0.0" iyy="1e-4" iyz="0.0" izz="2e-4"/>
    </inertial> -->
    <visual>
      <origin rpy="0 0 0" xyz="-0.0 -0.0 -0.004"/>
      <geometry>
        <mesh filename="/root/MyArmDescription/myarm_rl/data/ur5_six_description/meshes/link1_1.stl" scale="0.001 0.001 0.001"/>
      </geometry>
      <material name="silver"/>
    </visual>
    <collision>
      <origin rpy="0 0 0" xyz="-0.0 -0.0 -0.004"/>
      <geometry>
        <mesh filename="/root/MyArmDescription/myarm_rl/data/ur5_six_description/meshes/link1_1.stl" scale="0.001 0.001 0.001"/>
      </geometry>
    </collision>
  </link>
  <link name="link2_1">
    <!-- <inertial>
      <origin rpy="0 0 0" xyz="3.562181199145395e-07 -0.03139903655727208 0.14322344391589129"/>
      <mass value="1.1225393326346134"/>
      <inertia ixx="1e-4" ixy="0.0" ixz="0.0" iyy="1e-4" iyz="0.0" izz="2e-4"/>
    </inertial> -->
    <visual>
      <origin rpy="0 0 0" xyz="0.0 0.02542 -0.1"/>
      <geometry>
        <mesh filename="/root/MyArmDescription/myarm_rl/data/ur5_six_description/meshes/link2_1.stl" scale="0.001 0.001 0.001"/>
      </geometry>
      <material name="silver"/>
    </visual>
    <collision>
      <origin rpy="0 0 0" xyz="0.0 0.02542 -0.1"/>
      <geometry>
        <mesh filename="/root/MyArmDescription/myarm_rl/data/ur5_six_description/meshes/link2_1.stl" scale="0.001 0.001 0.001"/>
      </geometry>
    </collision>
  </link>
  <link name="link3_1">
    <!-- <inertial>
      <origin rpy="0 0 0" xyz="-6.959050393908114e-05 0.028506063082640698 0.10317461733698169"/>
      <mass value="2.4504885923855304"/>
      <inertia ixx="1e-4" ixy="0.0" ixz="0.0" iyy="1e-4" iyz="0.0" izz="2e-4"/>
    </inertial> -->
    <visual>
      <origin rpy="0 0 0" xyz="-1e-06 0.02642 -0.397159"/>
      <geometry>
        <mesh filename="/root/MyArmDescription/myarm_rl/data/ur5_six_description/meshes/link3_1.stl" scale="0.001 0.001 0.001"/>
      </geometry>
      <material name="silver"/>
    </visual>
    <collision>
      <origin rpy="0 0 0" xyz="-1e-06 0.02642 -0.397159"/>
      <geometry>
        <mesh filename="/root/MyArmDescription/myarm_rl/data/ur5_six_description/meshes/link3_1.stl" scale="0.001 0.001 0.001"/>
      </geometry>
    </collision>
  </link>
  <link name="link4_1">
    <!-- <inertial>
      <origin rpy="0 0 0" xyz="0.006059233920759447 -0.0003772521525039663 0.028617961409865278"/>
      <mass value="0.7725447173072004"/>
      <inertia ixx="1e-4" ixy="0.0" ixz="0.0" iyy="1e-4" iyz="0.0" izz="2e-4"/>
    </inertial> -->
    <visual>
      <origin rpy="0 0 0" xyz="0.000103 -0.003321 -0.677573"/>
      <geometry>
        <mesh filename="/root/MyArmDescription/myarm_rl/data/ur5_six_description/meshes/link4_1.stl" scale="0.001 0.001 0.001"/>
      </geometry>
      <material name="silver"/>
    </visual>
    <collision>
      <origin rpy="0 0 0" xyz="0.000103 -0.003321 -0.677573"/>
      <geometry>
        <mesh filename="/root/MyArmDescription/myarm_rl/data/ur5_six_description/meshes/link4_1.stl" scale="0.001 0.001 0.001"/>
      </geometry>
    </collision>
  </link>
  <link name="link5_1">
    <!-- <inertial>
      <origin rpy="0 0 0" xyz="0.00026645926067520986 -0.0220941657625503 0.045336799038450226"/>
      <mass value="0.6902971858072665"/>
      <inertia ixx="1e-4" ixy="0.0" ixz="0.0" iyy="1e-4" iyz="0.0" izz="2e-4"/>
    </inertial> -->
    <visual>
      <origin rpy="0 0 0" xyz="-0.004397 0.032636 -0.707573"/>
      <geometry>
        <mesh filename="/root/MyArmDescription/myarm_rl/data/ur5_six_description/meshes/link5_1.stl" scale="0.001 0.001 0.001"/>
      </geometry>
      <material name="silver"/>
    </visual>
    <collision>
      <origin rpy="0 0 0" xyz="-0.004397 0.032636 -0.707573"/>
      <geometry>
        <mesh filename="/root/MyArmDescription/myarm_rl/data/ur5_six_description/meshes/link5_1.stl" scale="0.001 0.001 0.001"/>
      </geometry>
    </collision>
  </link>
  <link name="link6_1">
    <!-- <inertial>
      <origin rpy="0 0 0" xyz="3.2145479142412295e-05 -2.1623190760156064e-07 0.0019996062622613664"/>
      <mass value="0.002466150233067908"/>
      <inertia ixx="1e-4" ixy="0.0" ixz="0.0" iyy="1e-4" iyz="0.0" izz="2e-4"/>
    </inertial> -->
    <visual>
      <origin rpy="0 0 0" xyz="-0.005583 0.05813 -0.780978"/>
      <geometry>
        <mesh filename="/root/MyArmDescription/myarm_rl/data/ur5_six_description/meshes/link6_1.stl" scale="0.001 0.001 0.001"/>
      </geometry>
      <material name="silver"/>
    </visual>
    <collision>
      <origin rpy="0 0 0" xyz="-0.005583 0.05813 -0.780978"/>
      <geometry>
        <mesh filename="/root/MyArmDescription/myarm_rl/data/ur5_six_description/meshes/link6_1.stl" scale="0.001 0.001 0.001"/>
      </geometry>
    </collision>
  </link>
  <joint name="j1" type="revolute">
    <origin rpy="0 0 0" xyz="0.0 0.0 0.004"/>
    <parent link="base_link"/>
    <child link="link1_1"/>
    <axis xyz="0.0 0.0 1.0"/>
    <limit effort="10" lower="-3.14" upper="3.14" velocity="10.0"/>
  </joint>
  <joint name="j2" type="revolute">
    <origin rpy="0 0 0" xyz="-0.0 -0.02542 0.096"/>
    <parent link="link1_1"/>
    <child link="link2_1"/>
    <axis xyz="0.0 1.0 0.0"/>
    <limit effort="10" lower="-2.26" upper="2.26" velocity="10.0"/>
  </joint>
  <joint name="j3" type="revolute">
    <origin rpy="0 0 0" xyz="1e-06 -0.001 0.297159"/>
    <parent link="link2_1"/>
    <child link="link3_1"/>
    <axis xyz="0.0 1.0 0.0"/>
    <limit effort="10" lower="-2.96" upper="2.96" velocity="10.0"/>
  </joint>
  <joint name="j4" type="revolute">
    <origin rpy="0 0 0" xyz="-0.000104 0.029741 0.280414"/>
    <parent link="link3_1"/>
    <child link="link4_1"/>
    <axis xyz="0.0 0.0 -1.0"/>
    <limit effort="10" lower="-3.14" upper="3.14" velocity="10.0"/>
  </joint>
  <joint name="j5" type="revolute">
    <origin rpy="0 0 0" xyz="0.0045 -0.035957 0.03"/>
    <parent link="link4_1"/>
    <child link="link5_1"/>
    <axis xyz="0.0 -1.0 -0.0"/>
    <limit effort="10" lower="-3.14" upper="3.14" velocity="10.0"/>
  </joint>
  <joint name="j6" type="revolute">
    <origin rpy="0 0 0" xyz="0.001186 -0.025494 0.073405"/>
    <parent link="link5_1"/>
    <child link="link6_1"/>
    <axis xyz="-0.016219 0.0 -0.999868"/>
    <limit effort="10" lower="-3.14" upper="3.14" velocity="10.0"/>
  </joint>
</robot>
